Workbook

Sheet ОБЩЕЕ
E2: кол | F2: сумма | G2: Раб. места | H2: Всего проектов: | I2: Общ сумма | J2: Общ раб места
D3: Реализованные | E3: =SUM(B13,B17,B20,B31,B32,B35,B43,B49,B50,B51,B52,B53,B62,B65,B68,B69,B73,B76,B90,B93,B94,B82,B87,B36,B30,B63,B98,B99,B100,B101,B102,B106,B95) -> 33 | F3: =SUM(K13,K17,K20,K30,K31,K32,K35,K36,K43,K49,K50,K51,K52,K53,K62,K63,K65,K68,K69,K73,K76,K82,K87,K90,K93,K94,K95,K98,K99,K100,K101,K102) -> 110899.94 | G3: =SUM(G13,G17,G20,G30,G36,G49,G50,G51,G52,G53,G62,G63,G68,G73,G76,G82,G87,G90,G93,G94,G95,G98,G99,G100,G101,G102) -> 2231 | H3: =SUM(E3:E7) -> 83 | I3: =SUM(F3:F7) -> 761416.17 | J3: =SUM(G3:G7) -> 12554
D4: Реализуемые (прошли РКС) | E4: =SUM(B15,B16,B19,B25,B26,B37,B40,B47,B48,B54,B55,B56,B71,B72,B91,B88,B85,B83,B81,B79,B74,B70,B67,B24,B44,B58,B42,B64) -> 28 | F4: =SUM(K16,K15,K19,K24,K25,K26,K37,K40,K42,K44,K47,K48,K54,K55,K56,K58,J64,K67,K70,K71,K72,K74,K79,K81,K83,K85,K88,K91) -> 404618.03 | G4: =SUM(G15,G16,G19,G24,G25,G26,G37,G40,G42,G44,G47,G48,G54,G55,G56,G58,G64,G67,G70,G71,G72,G74,G79,G83,G85,G81,G88,G91) -> 8274
D5: Расширение | E5: =SUM(B45,B60) -> 2 | F5: =SUM(K45,K60) -> 3972.2 | G5: =SUM(G60) -> 60
D6: Проблемные | E6: =SUM(B14,B21,B22,B23,B27,B39,B77,B80,B29,B28,B103,B104,B105,B59) -> 14 | F6: =SUM(I14,I22,I23,I21,I27,I39,I77,I80,I103,I104,I105,L59) -> 190415 | G6: =SUM(G14,G21,G22,G23,G27,G39,G77,G80,G103,G104,G104,G105) -> 1079
D7: Прост и исключенные | E7: =SUM(B78,B86,B33,B97,B96,B34) -> 6 | F7: =SUM(K33,K34,K78,K86) -> 51511 | G7: =SUM(G78,G86) -> 910
A10: № | B10: № | C10: Район | D10: Наименование компании | E10: Наименование проекта | F10: Стадия проекта | G10: Раб. Места | H10: Финансирование | I10: Стоимость, млн. тенге | M10: Ввод объекта по РКС | N10: Ввод объекта по факту | O10: Площадь земельного участка, га | P10: Мощность проекта и производительность | Q10: Текущий статус | R10: ФИО руководителя, контакты | S10: Меры господдержки | T10: долгота | U10: широта
H11: Собственные, АКК/БРК, Растениевод, СКО | I11: Всего по РКС | J11: Вне РКС | K11: Актуализир. сумма | L11: в т.ч. заемные
C12: Балхашский район
A13: 1 | B13: 1 | C13: Балхашский район | D13: ТОО «Неокарбон» - реализован, с.Баканас,ул.Сейфуллина №122А | E13: Переработки рисовой шелухи в производство древесноугольных брикетов и углерод-кремнистого композита | F13: Реализован | G13: 50 | I13: 386.8 | K13: =I13 -> 386.8 | M13: 2025 г. | N13: 2025 г. | O13: 0.9936 | P13: Углерод-кремнистый композит 216 тонн | Q13: Проект действует. На сегодня задействованы 9 работников. После достижения мощности будет увеличено до 50 раб.мест. | R13: Усенов Досжан, 87075655767 | S13: Подведение недостающей ИКИ, ЦН ЗУ - Прочие земли.
A14: 2 | B14: 1 | C14: Балхашский район | D14: ТОО «Тайда животноводство», Бакбактинский с/о | E14: Строительство агропромышленного комплекса по производству яиц | F14: Проблемный | G14: 68 | I14: 3120 | K14: =I14 -> 3120 | M14: 2027 г. | N14: 2027 г. | O14: 50 | P14: 100 млн. яиц в год | Q14: ПСД на государственной экспертизе с 28.04,2026 года, еще не получено, так как срок рассмотрения 1,5 месяца. Ориентировочный выход с ГЭ 20.06.2026г. В связи с неактивностью инвестора предлагается вынести на заседание РКС по отзыву ЗУ. | R14: Руководитель - Ян Цинхай, Уаджитова Амина Абдримовна, 87076408018 | S14: ЗУ на 5 лет. ЦН ЗУ - Прочие земли.
A15: 3 | B15: 1 | C15: Балхашский район | D15: ТОО «Баканас рис», Берекенский с/о | E15: Выращивание риса в Алматинской области | F15: Реализуемые | G15: 35 | I15: 600 | K15: =I15 -> 600 | M15: 2027 г. | N15: 2027 г. | O15: 707.6 | P15: от 5 000-7 000 тонн в год | Q15: В рамках реализации проекта выполняются работы по ограждению территории и проведению земляных работ. Приобретена сельскохозяйственная техника, обеспечено водоснабжение участка. В целях апробации технологии произведен посев риса на пробном участке площадью 50 га. Основной объем посевных работ запланирован на следующий год после получения финансирования от инвестора. В текущем году объем инвестиционных вложений составил 78,5 млн тенге. Реализация проекта осуществляется в соответствии с бизнес-планом. | R15: Рахманов Шавкат Бахтибаевич 87778880877, 87006804511 Орал | S15: ЗУ на 5 лет. ЦН ЗУ - Пашня орошаемая.
A16: 4 | B16: 1 | C16: Балхашский район | D16: ТОО «Баканас Байтак Агро» | E16: Строительство комплекса по переработке люцерны, кукурузы и других кормовых сельскохозяйственных культур | F16: Реализуемые | G16: 13 | I16: 869.1 | K16: 869.1 | M16: 2027 г. | O16: 13 | Q16: Получен государственный акт, однако в связи с некорректно указанным целевым назначением земельного участка документ сдан на корректировку. Начаты земельные работы. | S16: нет
A17: 5 | B17: 1 | C17: Балхашский район | D17: ТОО "СЭМ и КО" - реализован | E17: Предприятие мясного животноводства. Приобретение биологических активов в виде племенного КРС, МРС | F17: Реализован | G17: 99 | H17: СКО | K17: 5000 | L17: 5000 | M17: 2026 г. | P17: МРС - 5018 КРС - 6189 | Q17: Скот закуплен, предприятие действует, проблемных вопросов нет | R17: Абуталипова Асель | S17: Кредитов АПК (СКО)
C18: Енбекшиказахский район
A19: 6 | B19: 1 | C19: Енбекшиказахский район | D19: ТОО «Kazakhstan Central Asia Industrial Company., Ltd», Балтабайский с/о | E19: Переработка биологических отходов и производство органических, экологически чистых удобрений животного происхождения | F19: Реализуемые | G19: 30 | I19: 7200 | K19: =I19 -> 7200 | M19: 2026 г. | N19: 2026 г. | O19: 10 | P19: Мясокостная мука – 15 000 тонн, технический жир – 5 000 тонн | Q19: Оборудование из КНР доставлено. В настоящее время проводятся работы по его монтажу и установке. Для выполнения пусконаладочных работ ожидается поставка необходимых кабелей и проводов. Получение акта ввода объекта в эксплуатацию планируется в июле 2026 года. Реализация проекта осуществляется в соответствии с бизнес-планом. | R19: Руководитель - Sun Jinggang, 87762611499 Дуйсен
A20: 7 | B20: 1 | C20: Енбекшиказахский район | D20: ТОО «Qazaq Global Food JV», Тескенсуский с/о - реализован | E20: Строительство завода по переработке фруктов и овощей | F20: Реализован | G20: 128 | I20: 10000 | K20: =I20 -> 10000 | L20: 7000 | M20: 2026 г. | N20: 2026 | O20: 30 | P20: Переработка до 70 -80 тысяч тонн фруктов и овощей в год | Q20: Строительство завершено, оборудование завезено и установлено. Акт ввода в эксплуатацию на стадии оформления. Текущее время проводится работа по поиску поставщиков сырья для переработки. Торжественное открытие завода запланировно на 19.06.2026 г. | R20: 87025552708 Жуматаев Ержан Ерболатович | S20: ЗУ на 5 лет. ЦН ЗУ - Пастбища.
A21: 8 | B21: 1 | C21: Енбекшиказахский район | D21: ТОО «AGROFINANCE», ИЗ «Шелек» | E21: Строительство ультрасовременного фруктохранилища в Алматинской области | F21: Проблемный | G21: 40 | I21: 10500 | K21: =I21 -> 10500 | M21: 2028 г. | O21: 5 | P21: 10 000 тонн | Q21: Проект планируется к реализации на территории ИЗ «Шелек». Начало работ по подведению ИКИ ожидается через 2 месяца, завершение — в 2027 году. Проведены переговоры с инвестором. В настоящее время инвестор находится за границей. Представитель инвестора 30.06.2026 г. связался с работниками УКИЗ договорились о выезде 07.07.2026 г. чтоб рассмотреть предложения по новым ЗУ. Но сегодня так и не приехал, сославшись что выехал за границу, как будет в Алматы выйдет на связь. В связи с неактивностью инвестора предлагается вынести на заседание РКС по отзыву ЗУ. . | R21: 87781075132 Пасков Иван Степанович | S21: Размещение ИЗ «Шелек». ЦН ЗУ - Пастбища.
A22: 9 | B22: 1 | C22: Енбекшиказахский район | D22: TOО «Тепличный агропромышленный комплекс Синтай», Каражотинский с/о | E22: Выращивание в тепличном комплексе томаты, огурцы, перец, листья салатов, с последующей упаковкой для реализации. Комплекс будет состоять из 46 теплиц площадью каждой по 1 га, цех по упаковке, складские помещения, техничесие помещения. | F22: Проблемный | G22: 100 | I22: 3250 | K22: =I22 -> 3250 | M22: 2027 г. | O22: 50 | P22: 1 066 тыс тонн в год | Q22: На СВХ осуществляется таможенное оформление поставленного оборудования (6 экскаваторов) и металлических каркасов для теплиц. Подготовлены документы на изменение целевого назначения земельного участка под промышленное использование. После завершения процедуры планируется его выкуп. Реализация проекта затягивается в связи с разногласиями между инвестором и руководителем ТОО, препятствующими проведению проектных работ. В связи с неактивностью инвестора предлагается вынести на заседание РКС по отзыву ЗУ. | R22: Руководитель - Ибраев Куандык Аулиханович, инвестор - Ян Цинхай, Уаджитова Амина Абдримовна, 87076408018 | S22: ЗУ на 5 лет. ЦН ЗУ - Пастбища.
A23: 10 | B23: 1 | C23: Енбекшиказахский район | D23: ТОО «Батал Агро», Аватский с/о | E23: Производство семян кукурузы родительских форм | F23: Проблемный | G23: 85 | I23: 3500 | K23: =I23 -> 3500 | L23: 1500 | M23: 2027 г. | O23: 94 | P23: До 559 тонн семян | Q23: На полученном земельном участке площадью 94 га были проведены подготовительные работы к посевной кампании. Однако посевная не была осуществлена в связи с выявлением факта двойного правообладания на данный участок. По состоянию на настоящее время материалы обращения находятся на рассмотрении в Управлении полиции Енбекшиказахского района. По результатам рассмотрения в пределах компетенции органом полиции будет принято соответствующее процессуальное решение в порядке и сроки, установленные законодательством Республики Казахстан. | R23: 87773277919 Айдарбаев Берик Ерикович 8 705 265 8870 Елена (бухг) | S23: ЗУ на 49 лет. ЦН ЗУ - Пашня.
A24: 11 | B24: 1 | C24: Енбекшиказахский район | D24: ТОО «Дусан Инжиниринг», Акшиский с/о | E24: Организация МТФ на 1 200 голов КРС | F24: Реализуемые | G24: 50 | I24: 31840 | K24: =I24 -> 31840 | L24: 2400 | M24: 2034 г. | O24: 84 | P24: до 27 тыс. тонн в год | Q24: Приобретен земельный участок площадью 576 га, пробурена скважина. Закуплены две дождевальные установки производства КНР, достигнута договоренность о поставке еще трех установок. Получено АПЗ на систему орошения, ведется работа по оформлению лицензии на недропользование. По проекту МТФ разработана ПСД, получено положительное заключение государственной экспертизы. Приобретены четыре трактора с навесным оборудованием и прицепами, выполнены агротехнические работы, создано 9 рабочих мест. В текущем году планируется перевод 250 га земель на орошаемое земледелие с применением влагосберегающих технологий. Финансирование проекта планируется через АО «АКК». В связи с отсутствием финансирования строительство МТФ перенесено на 2027 год. Проект реализуется поэтапно: создание кормовой базы, строительство МТФ с приобретением маточного поголовья КРС, а также строительство перерабатывающих цехов и расширение поголовья. Объем инвестиций в проект в 2025 году составил 1,2 млрд тенге. Дополнительно в текущем году инвестировано 200 млн тенге. Реализация проекта осуществляется в соответствии с бизнес-планом. | R24: 8 775 224 7474 ЫСҚАҚ ТАЛҒАТ БАТЫРҰЛЫ | S24: ЗУ на 5 лет. ЦН ЗУ - Пастбища.
A25: 12 | B25: 1 | C25: Енбекшиказахский район | D25: ТОО «QazEcoDan», Масакский с/о | E25: Строительство Элеватора -комплекса по приемке, очистке, сушке и хранению зерновых и масленичных культур, производству комбинированных кормов | F25: Реализуемые | G25: 51 | I25: 7975.333 | K25: =I25 -> 7975.333 | M25: 1 этап - 2026 г. 2 этап - 2027 г. | N25: 1 этап - 2026 г. 2 этап - 2027 г. | O25: 9.6 | P25: Очистка, сушка: 40-60 тонн/час Хранение в силосах: 30 тыс. тонн Мощностью производства кормов 120 тонн/сутки | Q25: Строительство I очереди проекта завершено на 98%, акт ввода объекта в эксплуатацию находится на согласовании. Объем инвестиций составил 5,8 млрд тенге. Завершено строительство основных производственных объектов, включая сушильную печь, силосы, ЛЭП-35, газгольдер, железнодорожный тупик и монтаж технологического оборудования. На завершающей стадии находятся работы по объектам вспомогательной инфраструктуры. Для повышения эффективности проекта требуется подключение к природному газу, что позволит снизить себестоимость сушки зерновых культур. Также рассматривается расширение железнодорожного тупика путем строительства трех дополнительных веток. Вопрос строительства газопровода от п. Казтай Ултараков прорабатывается с местными исполнительными органами. | R25: 87716111117 Ерлан руководитель проекта, Руководитель Кайралапин Казбек +7 701 227 0091 | S25: ЗУ на 10 лет. ЦН ЗУ - Пастбища.
A26: 13 | B26: 1 | C26: Енбекшиказахский район | D26: ТОО «Мың жылқы шаруа қожалығы», Масакский с/о Саймасай, Каратурык. | E26: Строительство и организация деятельности конефермы | F26: Реализуемые | G26: 20 | I26: 1576.6 | K26: =I26 -> 1576.6 | M26: 2027 г. | O26: 4457.7 | P26: 1 000 лошадей | Q26: Введутся работы по подготовке к СМР, произведен закуп лошадей в кол-ве 360 голов на 432 млн тенге. На 5 га планируется строительство кошары, навесов, загонов, остальную землю использовать под пастбище. | R26: Руководитель - Оразалин Галымжан Серикович 87011116911 | S26: ЗУ на 5 лет. ЦН ЗУ - Пастбища.
A27: 14 | B27: 1 | C27: Енбекшиказахский район | D27: ТОО «Kasym ASES», Рахатский с/о | E27: Завод по переработке куриных лап | F27: Проблемный | G27: 200 | I27: 1221 | K27: =I27 -> 1221 | M27: 2026 г. | N27: 2027 г. | O27: 3 | P27: 15 000 тонн/год | Q27: Произведена смена целевого назначения земельного участка на промышленное использование, на стадии получения государственного акта. Имеется частичная инфраструктура: получены технические условия по электроснабжению, подведено освещение, водоснабжение обеспечено через скважину, газоснабжение отсутствует, подъездной путь требует отсыпки. В связи с планируемой сменой учредителя (вхождение гражданина Турции с соответствующим опытом и инвестициями) и руководителя ТОО в июле текущего года, работы по подаче заявки на АПЗ не проводились. | R27: Жолдыбай Есентай руководитель и учредитель, представитель Адильбек Аргинбаев 8 778 358 9621 | S27: ЦН ЗУ - пастбища
A28: 15 | B28: 1 | C28: Енбекшиказахский район | D28: ТОО "ПОМОНА" | E28: Строительство и эксплуатация систем влагосберегающих технологий для выращивание кукурузы на зерно | F28: Инвестиционные проекты реализуемые по программе развития растениеводства. | H28: Растениевод | K28: 361.8 | M28: 2026 г. | O28: 250 | P28: 794 тонны в год | Q28: Ранее несоответствующее договору оборудование возвращено поставщику. На текущий момент приобретено новое оборудование, которое находится на складе поставщика. Поставка на объект и завершение монтажных работ запланированы на август 2026 года. Приобретается: Дождевальная машина фронтального типа 2 шт и дождевальная машина кругового действия - 8 шт. | R28: Аяпбергенов Бауржан Болатович
A29: 16 | B29: 1 | C29: Енбекшиказахский район | D29: ТОО "Revival of apples" | E29: Строительство и эксплуатация систем влагосберегающих технологий для выращивание кукурузы на зерно | F29: Инвестиционные проекты реализуемые по программе развития растениеводства. | H29: Растениевод | K29: 520 | M29: 2026 г. | O29: 400 | P29: 1 253 тонн в год | Q29: На площадку реализации проекта поставлена сельскохозяйственная техника, включая разбрасыватели жидкого и твердого навоза, а также кормораздатчики. Ранее несоответствующее договору оборудование возвращено поставщику. Новое оборудование приобретено и находится на складе поставщика, его поставка и монтаж запланированы на август 2026 года. Приобретается: Дождевальная машина фронтального типа 2 шт и дождевальная машина кругового действия - 8 шт. | R29: Молдаш Әсел
A30: 17 | B30: 1 | C30: Енбекшиказахский район | D30: ТОО FRESH FISH KZ | E30: Рыбоводство | F30: Реализуемые | G30: 20 | H30: СКО | K30: 651.3 | L30: 500 | M30: 2026 г. | P30: 1512 тонн рыбы в год | Q30: Конкурсная комиссия одобрило финансирование по программе кредитование в сфере АПК (по опыту СКО) на приобретение оборудования для глубокой переработки форели и других видов рыб: свежей, мороженной, сушеной и копченой рыбы, а также красной икры. | R30: Мурат Аманжол, 87756327171
A31: 18 | B31: 1 | C31: Енбекшиказахский район | D31: КХ «Айдарбаев» - реализован | E31: Расширение молочно товарной фермы | F31: Реализован | H31: СКО | K31: 650 | L31: 650 | M31: 2026 г. | P31: 1270 голов, 6200 тонн в год | Q31: МТФ работает, проблемных вопросов нет | R31: Айдарбаев Ерик Серикович
A32: 19 | B32: 1 | C32: Енбекшиказахский район | D32: ТОО «ABDI AGRO» -- реализован | E32: Строительство молочно товарной фермы | F32: Реализован | H32: СКО | K32: 1314.2 | L32: 1314.2 | M32: 2026 г. | P32: 400 голов, 2000 тонн в год | Q32: МТФ работает, проблемных вопросов нет | R32: Абдиев Ержан Шубаевич 87015558622
A33: 20 | B33: 1 | C33: Енбекшиказахский район | D33: ИП «Тұржан Дәулетхан Мәжитұлы» | E33: Строительство молочно товарной фермы | F33: Простаивающий | H33: СКО | K33: 2000 | L33: 2000 | M33: 2026 г. | P33: 612 голов, 2700 тонн в год | Q33: Строительство МТФ завершено, оборудование доильного зала установлено, ожидается пусконаладка, скот не поставлен, но оплата произведена. В связи с неисполнением обязательств, АО "СПК Конаев" подал исковое заявление о погашении просроченной задолженности. | R33: Маметов Марат
A34: 21 | B34: 1 | C34: Енбекшиказахский район | D34: АО «Агропромышленная компания Адал» - реализован | E34: Современная молочно-товарная ферма | F34: Реализован | H34: СКО | K34: 1833.8 | L34: 1833.8 | M34: 2026 г. | P34: 2371 голов, 11160 тонн в год | Q34: Строительство дополнительного корпуса МТФ и нового доильного зала завершено, монтаж оборудования коровника и доильного зала завершено. | R34: Смаилов Серик
A35: 22 | B35: 1 | C35: Енбекшиказахский район | D35: КХ «Алимжанов» - реализован | E35: Расширение молочно товарной фермы | F35: Реализован | H35: СКО | K35: 199.5 | L35: 199.5 | M35: 2025 г. | P35: 831 голов, 3500 тонн в год | Q35: МТФ работает, проблемных вопросов нет | R35: Алимжанов Тілек
A36: 23 | B36: 1 | C36: Енбекшиказахский район | D36: ТОО «Абди Агро» - реализован | E36: Строительство и эксплуатация систем влагосберегающих технологий | F36: Реализован | G36: 10 | I36: 601.8 | K36: 601.8 | M36: 2026 г. | P36: 400 голов, 2000 тонн в год | Q36: МТФ работает, проблемных вопросов нет | R36: Абдиев Ержан Шубаевич
A37: 24 | B37: 1 | C37: Енбекшиказахский район | D37: ТОО «K&J AGRO» | E37: Строительство теплицы по выращиванию шампиньонов | F37: Реализуемые | G37: 100 | I37: 1500 | K37: 1500 | M37: 2029 г. | O37: 4 | P37: 2 тыс. тонн в год | Q37: Планируется заказ проектно-сметной документации. Ожидает подведения инфраструктуры на ИЗ «Шелек» | R37: Ракыш Темирлан | S37: нет
C38: Жамбылский район
A39: 25 | B39: 1 | C39: Жамбылский район | D39: TOO «DARIA Company», Шолаккаргалинский с/о | E39: Тепличный комплекс | F39: Проблемный | G39: 70 | I39: 15000 | K39: =I39 -> 15000 | L39: 15000 | M39: 2027 г. | O39: 15 | P39: 3 тыс тонн год | Q39: В связи с несоответствием ранее полученных технических условий по электроснабжению и газоснабжению требованиям проекта проводится перепроектирование линии электропередачи (срок завершения — до 15.06.2026 г.). После получения обновлённых решений проект будет направлен на государственную экспертизу. Финансирование планируется через АО «Банк Развития Казахстана» (БРК). Работы в настоящее время не ведутся. В связи с неактивностью инвестора предлагается вынести на заседание РКС по отзыву ЗУ. | R39: Руководитель - Мацыгин Дмитрий Вениаминович, 8 777 229 5000 Маргулан; Акмарал 8 747 701 87 74 | S39: ЗУ на 3 года. ЦН ЗУ - пашня орошаемая
A40: 26 | B40: 1 | C40: Жамбылский район | D40: ТОО «Кок Тениз К», Темиржолский с/о | E40: Расширение мощностей по переработке кукурузы с 10 000 до 50 000 тонн в год | F40: Реализуемые проекты, по линии кредитования АПК по опыту СКО | G40: 10 | H40: СКО | K40: 1800 | L40: 1800 | M40: 2027 г. | P40: 50 тыс тонн в год | Q40: Конкурсная комиссия одобрило финансирование по программе кредитование в сфере АПК (по опыту СКО) на приобретение оборудования для модернизации и расширение действующего производства в сумме 1,8 млрд.тенге. | R40: Кошкинов Ержан Абдулинович +77015396668, 8 706 407 9137 Ерасыл - сын | S40: ЗУ на 10 лет. ЦН ЗУ - пашня богарная
D41: ТОО «Кок Тениз К», Темиржолский с/о | E41: Строительство и эксплуатация систем влагосберегающих технологий | F41: Реализуемые | G41: 10 | I41: 750 | M41: 2027 г. | O41: 3080 | Q41: 15.06.2026 г. планируется доставка трех дождевальных установок для орошения земельных участков общей площадью 200 га. Проводится работа по выбору поставщика дождевальных установок для организации орошения 1 000 га земель, предназначенных под многолетние культуры. Объем инвестиций в проект в текущем году составляет 750 млн тенге. Реализация проекта осуществляется в соответствии с утвержденным бизнес-планом.
A42: 28 | B42: 1 | C42: Жамбылский район | D42: ТОО «Научно производственный центр Генофонд» | E42: Строительство МТФ на 600 голов КРС | F42: Реализуемые | G42: 18 | H42: СКО | K42: 2400 | L42: 1400 | M42: 2027 г. | P42: 600 голов, 5000 тон в год | Q42: Завршение строительствв МТФ планируется в до конца июля месяца текущего года, для приобретения оборудования МТФ, доильного зала, КРС, Конкурсной комиссией утверждено финансирование на 1,4 млрд тенге. Финансирование планируется в текущем месяце. | R42: 8-701 303 5050 Толемисов Махан Кенжегазинович, бухгалтер - 8-701 303 22 88 Кумис Мурзалинова | S42: ПСД на стадии разработки, представлен государственный акт на земельный участок
A43: 29 | B43: 1 | C43: Жамбылский район | D43: ИП Сарсембаева Р.Г. - реализован | E43: Строительство и эксплуатация систем влагосберегающих технологий для выращивание кукурузы на зерно | F43: Реализован | H43: Растениевод | K43: 941 | M43: 2025 г. | N43: 2025 г. | O43: 488 | P43: 2258 тонн в год | Q43: Приобретенное оборудование введено в эксплуатацию, проблемных вопросов нет. Приобретено: Дождевальные машины кругового типа - 9шт.так же система капельного орошения на 180 га. | R43: Абулгазинов Марлен 87011112789
...

Sheet Реализованные
D2: кол | E2: сумма | F2: Раб. места
C3: Реализованные | D3: 33 | E3: 110899.94 | F3: 2231
A5: № | B5: № | C5: Район | D5: Наименование компании | E5: Наименование проекта | F5: Стадия проекта | G5: Раб. Места | H5: Финансирование | I5: Стоимость, млн. тенге | M5: Ввод объекта по РКС | N5: Ввод объекта по факту | O5: Площадь земельного участка, га | P5: Мощность проекта и производительность | Q5: Текущий статус | R5: ФИО руководителя, контакты | S5: Меры господдержки
H6: Собственные, АКК/БРК, Растениевод, СКО | I6: Всего по РКС | J6: Вне РКС | K6: Актуализир. сумма | L6: в т.ч. заемные
A7: 1 | C7: Балхашский район | D7: ТОО «Неокарбон» - реализован, с.Баканас,ул.Сейфуллина №122А | E7: Строительство наружных сетей газоснабжение производственной базы переработки рисовой шелухи в производство древесноугольных брикетов и углерод-кремнистого композита | F7: Реализован | G7: 50 | I7: 386.8 | K7: =I7 -> 386.8 | M7: 2025 г. | N7: 2025 г. | O7: 0.9936 | P7: Углерод-кремнистый композит 216 тонн | Q7: Проект действует. На сегодня задействованы 9 работников. После достижения мощности будет увеличено до 50 раб.мест. | R7: Усенов Досжан, 87075655767 | S7: Подведение недостающей ИКИ, ЦН ЗУ - Прочие земли.
A8: 2 | C8: Балхашский район | D8: ТОО "СЭМ и КО" | E8: Предприятие мясного животноводства. Приобретение биологических активов в виде племенного КРС, МРС | G8: 99 | H8: СКО | K8: 5000 | L8: 5000 | P8: МРС - 5018 КРС - 6189 | Q8: Скот закуплен, предприятие действует, проблемных вопросов нет | R8: Абуталипова Асель | S8: Кредитов АПК (СКО)
A9: 3 | C9: Енбекшиказахский район | D9: ТОО «Qazaq Global Food JV», Тескенсуский с/о | E9: Строительство завода по переработке фруктов и овощей (производству концентратов фруктовых соков, овощных и фруктовых пюре с инфраструктурой хранения сортировки и упаковки фруктов) | F9: Реализован | G9: 128 | I9: 10000 | K9: 10000 | L9: 7000 | M9: 2026 г. | N9: 2026 | O9: 30 | P9: Переработка до 70 -80 тысяч тонн фруктов и овощей в год | Q9: Строительство завершено, оборудование завезено и установлено. Акт ввода в эксплуатацию на стадии оформления. Текущее время проводится работа по поиску поставщиков сырья для переработки. Торжественное открытие завода запланировно на 19.06.2026 г. | R9: 87025552708 Жуматаев Ержан Ерболатович | S9: ЗУ на 5 лет. ЦН ЗУ - Пастбища.
A10: 4 | C10: Енбекшиказахский район | D10: ТОО FRESH FISH KZ | E10: Рыбоводство | F10: Реализуемые проекты, по линии кредитования АПК по опыту СКО | G10: 20 | H10: СКО | K10: 651.3 | L10: 500 | P10: 1512 тонн рыбы в год | Q10: Конкурсная комиссия одобрило финансирование по программе кредитование в сфере АПК (по опыту СКО) на приобретение оборудования для глубокой переработки форели и других видов рыб: свежей, мороженной, сушеной и копченой рыбы, а также красной икры. | R10: Мурат Аманжол, 87756327171
A11: 5 | C11: Енбекшиказахский район | D11: КХ «Айдарбаев» | E11: Расширение молочно товарной фермы | F11: Реализуемые проекты, по линии кредитования АПК по опыту СКО | H11: СКО | K11: 650 | L11: 650 | P11: 1270 голов, 6200 тонн в год | Q11: МТФ работает, проблемных вопросов нет | R11: Айдарбаев Ерик Серикович
A12: 6 | C12: Енбекшиказахский район | D12: ТОО «ABDI AGRO» | E12: Строительство молочно товарной фермы | F12: Реализуемые проекты, по линии кредитования АПК по опыту СКО | H12: СКО | K12: 1314.2 | L12: 1314.2 | P12: 400 голов, 2000 тонн в год | Q12: МТФ работает, проблемных вопросов нет | R12: Абдиев Ержан Шубаевич 87015558622
A13: 7 | C13: Енбекшиказахский район | D13: КХ «Алимжанов» | E13: Расширение молочно товарной фермы | F13: Реализуемые проекты, по линии кредитования АПК по опыту СКО | H13: СКО | K13: 199.5 | L13: 199.5 | P13: 831 голов, 3500 тонн в год | Q13: МТФ работает, проблемных вопросов нет | R13: Алимжанов Тілек
A14: 8 | C14: Енбекшиказахский район | D14: ТОО «Абди Агро» | E14: Строительство и эксплуатация систем влагосберегающих технологий | G14: 10 | I14: 601.8 | K14: 601.8 | R14: Абдиев Ержан Шубаевич
A15: 9 | C15: Жамбылский район | D15: ИП Сарсембаева Р.Г. | E15: Строительство и эксплуатация систем влагосберегающих технологий для выращивание кукурузы на зерно | F15: Инвестиционные проекты реализуемые по программе развития растениеводства. | H15: Растениевод | K15: 941 | P15: 2258 тонн в год | Q15: Приобретенное оборудование введено в эксплуатацию, проблемных вопросов нет | R15: Абулгазинов Марлен 87011112789
A16: 10 | C16: Илийский район | D16: АО "Каскеленское" | E16: Строительство и эксплуатация систем влагосберегающих технологий для выращивание кукурузы на зерно | F16: Инвестиционные проекты реализуемые по программе развития растениеводства. | G16: 20 | H16: Растениевод | K16: 386 | O16: 5882 | P16: 930 тонн в год | Q16: Приобретенное оборудование введено в эксплуатацию, проблемных вопросов нет
A17: 11 | C17: Илийский район | D17: ТОО Каргалы Крахмал | E17: Строительство и эксплуатация систем влагосберегающих технологий для выращивания кукурузы на зерно | F17: Инвестиционные проекты реализуемые по программе развития растениеводства. | G17: 10 | H17: Растениевод | K17: 142 | O17: 416 | P17: 343 тонн в год | Q17: Приобретенное оборудование введено в эксплуатацию, проблемных вопросов нет
A18: 12 | C18: Илийский район | D18: ТОО «Научно производственный центр Генофонд» | E18: Расширение молочно товарной фермы | F18: Реализуемые проекты, по линии кредитования АПК по опыту СКО | G18: 19 | H18: СКО | K18: 553.6 | L18: 553.6 | O18: 1162 | P18: 1800 голов, 7440 тонн в год | Q18: МТФ работает, проблемных вопросов нет | R18: Толемисов Махан
A19: 13 | C19: Илийский район | D19: ТОО «Ризык Агро» | E19: Расширение молочно товарной фермы | F19: Реализуемые проекты, по линии кредитования АПК по опыту СКО | G19: 23 | H19: СКО | K19: 1209.8 | L19: 1209.8 | O19: 5400 | P19: 629 голов, 3100 тонн в год | Q19: МТФ работает, проблемных вопросов нет | R19: Абулгазинов Марлен
A20: 14 | C20: Илийский район | D20: ТОО «Ак сут LLC» | E20: Расширение молочно товарной фермы | F20: Реализуемые проекты, по линии кредитования АПК по опыту СКО | G20: 50 | H20: СКО | K20: 300.7 | L20: 300.7 | O20: 184 | P20: 2592 голов, 6900 тонн в год | Q20: МТФ работает, проблемных вопросов нет | R20: Сембай Елжас
A21: 15 | C21: Талгарский район | D21: СПК «Племзавод «Алматы» - реализован, участок Малайсары. | E21: Развитие овцеводства породы Иль-Де-Франс в Жетысу | F21: Реализован | G21: 100 | I21: 750 | K21: 1500 | L21: 0 | M21: 2025 г. | O21: 2512 | P21: 1000 голов, 200 тонн мяса в год | Q21: Проект реализован. Ведутся селекционные работы: из г. Минск завезено 100 голов баранов-производителей породы Иль-де-Франс, сформировано маточное стадо численностью 1 500 голов. На площади 680 га проводятся работы по переводу земель в категорию орошаемых для внедрения влагосберегающих технологий. Получены технические условия на подключение к электрическим сетям, проектно-сметная документация прошла государственную экспертизу. В настоящее время осуществляется приобретение дождевальных (фрегатных) установок, монтаж которых запланирован на осень текущего года. | R21: Ахметжанов Рустем Кажиканович, 87775146500 | S21: ЗУ на 49 лет. ЦН ЗУ - 528 га-орошаемая пашня, 1 984 га- пастбище.
A22: 16 | C22: Талгарский район | D22: ТОО COFCO TRANS Бин 250640019716 | E22: Элеватор по производству кормовой муки | G22: 23 | H22: собственные средства | K22: 5500 | M22: 2026 г. | P22: 293 тыс тонн | Q22: На сегодняшний день строительно-монтажные работы выполнены на 75 %. Работы ведутся в соответствии с утвержденным графиком. Завершение проекта планируется в течение ближайших двух месяцев. В настоящее время на объекте продолжаются основные строительные и организационные мероприятия, направленные на своевременное завершение всех предусмотренных этапов работ. С учетом текущих темпов реализации проекта, полный ввод объекта в эксплуатацию ожидается до начала уборочной кампании урожая.
A23: 17 | C23: Талгарский район | D23: ТОО «Байсерке Агро» | E23: Расширение молочно товарной фермы | F23: Реализуемые проекты, по линии кредитования АПК по опыту СКО | H23: СКО | K23: 500 | L23: 500 | P23: 1125 голов, 4650 тонн в год | Q23: МТФ работает, проблемных вопросов нет | R23: Жунисбеков Галыжан
A24: 18 | C24: Уйгурский район | D24: ТОО "Eco Park Tour" | E24: Строительство и эксплуатация систем влагосберегающих технологий длч сада по выращиванию яблок и абрикоса | F24: Инвестиционные проекты реализуемые по программе развития растениеводства. | G24: 10 | H24: Растениевод | J24: 217 | K24: 217 | N24: 2017 декабрь | O24: 1,01 га | P24: 537 тонн в год | Q24: Реализованный проект | R24: Абдулминов Бахтияр Баратович | S24: 1,01 га
A25: 19 | C25: Уйгурский район | D25: ТОО Kolzhat Agro | E25: Строительство и эксплуатация систем влагосберегающих технологий для выращивания люцерны | F25: Инвестиционные проекты реализуемые по программе развития растениеводства. | H25: Растениевод | K25: 527.237 | O25: 1490 | P25: 1249 тонн люцерны с 1490 га | Q25: Приобретенное оборудование введено в эксплуатацию, проблемных вопросов нет | R25: Нимилостев Петр Петрович
A26: 20 | C26: Уйгурский район | D26: ТОО «Асем калжат» | G26: 180 | I26: 7500 | K26: 7500
A27: 21 | C27: г.Конаев | D27: ТОО «Оспанова Девелопмент» - реализован. | E27: Строительство рыбопромышленного комплекса | F27: Реализован | G27: 500 | I27: 9800 | K27: 9800 | L27: 300 | M27: 2023 г. | O27: 27 | P27: 1 тыс. тонн рыбы в год | Q27: Первый этап проекта реализован и введен в эксплуатацию в октябре 2023 года. В настоящее время осуществляется выращивание форели и беррамунди (морского окуня). От реализации последующих этапов проекта, предусматривавших выращивание карпа, инвестор отказался в связи с экономической нерентабельностью. Согласно Правилам субсидирования инвестиционных вложений, сумма возмещения затрат по первому этапу составила 90 млн тенге, что соответствует лишь 0,85 % от стоимости первого этапа проекта. | R27: Бектемисов Максим Сакенович | S27: Подведение недостающей инфраструктуры ЦН ЗУ - прочие земли
A28: 22 | C28: г.Конаев | D28: ТОО «Қапшагай бидай өнімдері» | G28: 350 | I28: 12000 | K28: 12000
A29: 23 | C29: г.Алатау | D29: ТОО «ФрутАрт» | G29: 247 | I29: 42800 | K29: 42800
A30: 24 | C30: Райымбекский район | D30: ТОО "Сарыбастау - ББ" | E30: Строительство и эксплуатация систем влагосберегающих технологий для выращивания картофеля | F30: Инвестиционные проекты реализуемые по программе развития растениеводства. | G30: 10 | H30: Растениевод | K30: 407 | O30: 200 | P30: 1500 тонн картофеля | Q30: В текущем году освоено 169 га из запланированных 200 га. На площади 50 га произведён посев картофеля, на 110 га — ячменя. РКС не проходили. | S30: нет
A31: 25 | C31: Кегенский район | D31: СПК «Талас» | E31: Расширение молочно-товарной фермы | F31: Реализуемые проекты, по линии кредитования АПК по опыту СКО | G31: 50 | H31: СКО | I31: 492 | K31: 492 | L31: 492 | M31: 2025 г. | O31: 745 | P31: 422 голов, 1375 тонн в год | Q31: Ведутся СМР по расширению. МТФ работает, проблемных вопросов нет | R31: Жамбаев Жусип Ахметказиевич 87010813468. | S31: З/У
A32: 26 | C32: Кегенский район | D32: ТОО «KeгeнMяcПpoм» | E32: Мясокомбинат с предубойным откормочным комплексом | F32: Реализован | G32: 50 | I32: 2700 | K32: 2700 | M32: 2025 г. | N32: 2025 г. | O32: 380 | P32: 10 тонн мяса в сутки | Q32: Все оборудование на площадке для убоя скота прошло полную проверку. На объект строительства выдан технический паспорт (техпаспорт). | R32: Баймолдаев Токтар Аскарович +7 701 311 1151 | S32: З/У
A33: 27 | C33: Кегенский район | D33: Производство тонкой шерсти ТОО «MERGEN HOLDING» | E33: Строительство производственной базы по переработке шерсти «MERGEN HOLDING» | G33: 200 | H33: собственные средства | K33: 1500 | M33: 12.2026 г. | P33: 2 тыс тонн | Q33: Наличие земельного участка; наличие ПСД (АПЗ, рабочий проект, эскизный проект, заключение); Активно ведутся СМР, выполняется комплекс земляных работ, включая разработку и подготовку грунта. Параллельно осуществляются бетонные работы по устройству основных конструктивных элементов. Ведётся монтаж металлоконструкций в соответствии с утверждённой ПСД
A34: 28 | C34: Карасайский район | D34: ИП «Baitelov» | E34: Расширение садкового рыбоводного хозяйства по выращиванию ценных видов рыб с объемом 120 тонн в год | G34: 6 | H34: собственные средства | I34: 120 | K34: 120 | M34: 2025 | P34: 120 тонн форели в год | Q34: Рыбоводное хозяйство расположен на земельном участке площадью 33,5 га. Для выращивания молоди рыбы имеются 5 естественных прудов общей площадью 2326,4 м кв., которые предназначены для выращивания мальков форели до товарной массы. Пруды оборудованы садками общей площадью 7861 м3 оснащены магистральными каналами водоподачи и дренажной системой. Водоснабжение производится из артезианской скважины с температурным режимом 13-16°С. Рыбоводное хозяйство оснащен необходимой инфраструктурой и оборудованием включая склад для хранения кормов площадью 0,5 м2. Малька форели карпа закупают от местных производителей.
A35: 29 | C35: Кегенский район | D35: Командитное товарищество «Great Steppe Heritage» | E35: Расширение и автоматизация садковой линии | G35: 28 | H35: собств. ср-ва 400 млн, заемные 1,650 млрд. | I35: 2050 | K35: 2050 | M35: 2025 | P35: 500 тонн форели в год | Q35: Договор с ТОО «Мойнакская ГЭС» на 10 лет по аренде водной глади для установки садков подписан. Установлены 12 садков диаметром 22 м. Провел работу по зарыблению в количестве 250 тыс. штук мальками форели средней массой 12 гр. Корма используются импортные – ALLER AQUA. Кроме того, 2025 году планируется расширение и автоматизация садковой линии. | R35: Байзаков Нурлан диретор 87017557507 Байкен Бекетаевич 87028216346
A36: 30 | C36: Енбекшиказахский район | D36: ТОО «TogizBulaq» | E36: Создание прудового рыбоводного хозяйства по выращиванию ценных видов рыб с объемом 360 тонн в год | G36: 21 | H36: собственные средства | I36: 200 | K36: 200 | M36: 2025 | P36: 360 тонн форели в год | Q36: В мае 2022 года начато строительство рыбоводного комплекса на земельном участке площадью 75 гектаров. Проектно-сметная документация прошла государственную экспертизу. Проведена работа по установке оборудования (бассейны, инкубационные аппараты). Запуск 1 этапа выращивание форели начато в начале 2024 года. Проделано 50% работы.
A37: 31 | C37: Енбекшиказахский район | D37: ТОО "АгроАкваКомплекс" | E37: Расширение прудового рыбоводного хозяйства по выращиванию ценных видов рыб с объемом 279 тонн в год | G37: 14 | H37: заемные средства | I37: 300 | K37: 300 | M37: 2025 | P37: 279 тонн карп.форели | Q37: имеется 7 прудов, планируется увеличить до 20
A38: 32 | C38: Жамбылский район | D38: ТОО " ТехноСнаб 2002" | E38: Создание УЗВ Рыбопромышленный комплекс по выращиванию форели и осетра | G38: 13 | H38: собственные средства | I38: 450 | K38: 450 | M38: 2025 | P38: 150-200 форель и осетра | Q38: Ввод в эксплуатацию в августе 2025 г.
A39: 33 | C39: Илийский район | D39: ТОО "Кайнар Балык" | E39: Инкуб.цех, 15 садков | H39: собственные средства | M39: 2026

Sheet Реализуемые
D2: кол | E2: сумма | F2: Раб. места
C3: Реализуемые | D3: 28 | E3: 404318.03 | F3: 8284
A7: № | B7: № | C7: Район | D7: Наименование компании | E7: Наименование проекта | F7: Стадия проекта | G7: Раб. Места | H7: Финансирование | I7: Стоимость, млн. тенге | M7: Ввод объекта по РКС | N7: Ввод объекта по факту | O7: Площадь земельного участка, га | P7: Мощность проекта и производительность | Q7: Текущий статус | R7: ФИО руководителя, контакты | S7: Меры господдержки
H8: Собственные, АКК/БРК, Растениевод, СКО | I8: Всего по РКС | J8: Вне РКС | K8: Актуализир. сумма | L8: в т.ч. заемные
A9: 1 | C9: Балхашский район | D9: ТОО «Баканас рис», Берекенский с/о | E9: Выращивание риса в Алматинской области | F9: Реализуемые проекты, прошедшие РКС | G9: 35 | I9: 600 | K9: 600 | M9: 2027 г. | N9: 2027 г. | O9: 707.6 | P9: от 5 000-7 000 тонн в год | Q9: В рамках реализации проекта выполняются работы по ограждению территории и проведению земляных работ. Приобретена сельскохозяйственная техника, обеспечено водоснабжение участка. В целях апробации технологии произведен посев риса на пробном участке площадью 50 га. Основной объем посевных работ запланирован на следующий год после получения финансирования от инвестора. В текущем году объем инвестиционных вложений составил 78,5 млн тенге. Реализация проекта осуществляется в соответствии с бизнес-планом. | R9: Рахманов Шавкат Бахтибаевич 87778880877, 87006804511 Орал | S9: ЗУ на 5 лет. ЦН ЗУ - Пашня орошаемая.
A10: 2 | C10: Балхашский район | D10: ТОО «Баканас Байтак Агро» | E10: Строительство комплекса по переработке люцерны, кукурузы и других кормовых сельскохозяйственных культур | F10: Реализуемые проекты, прошедшие РКС в 2026 | G10: 13 | I10: 869.1 | K10: 869.1 | M10: 2027 | O10: 13 | Q10: Получен государственный акт, однако в связи с некорректно указанным целевым назначением земельного участка документ сдан на корректировку. Начаты земельные работы. | S10: нет
A11: 3 | C11: Енбекшиказахский район | D11: ТОО «Kazakhstan Central Asia Industrial Company., Ltd», Балтабайский с/о | E11: Переработка биологических отходов и производство органических, экологически чистых удобрений животного происхождения | F11: Реализуемые проекты, прошедшие РКС | G11: 30 | I11: 7200 | K11: 7200 | M11: 2026 | N11: 2026 | O11: 10 | P11: Мясокостная мука – 15 000 тонн, технический жир – 5 000 тонн | Q11: Оборудование из КНР доставлено. В настоящее время проводятся работы по его монтажу и установке. Для выполнения пусконаладочных работ ожидается поставка необходимых кабелей и проводов. Получение акта ввода объекта в эксплуатацию планируется в июле 2026 года. Реализация проекта осуществляется в соответствии с бизнес-планом. | R11: Руководитель - Sun Jinggang, 87762611499 Дуйсен
A12: 4 | C12: Енбекшиказахский район | D12: ТОО «Дусан Инжиниринг», Акшиский с/о | E12: Организация МТФ на 1 200 голов КРС | F12: Реализуемые проекты, прошедшие РКС | G12: 50 | I12: 31840 | K12: 31840 | L12: 2400 | M12: 2034 г. | O12: 84 | P12: до 27 тыс. тонн в год | Q12: Приобретен земельный участок площадью 576 га, пробурена скважина. Закуплены две дождевальные установки производства КНР, достигнута договоренность о поставке еще трех установок. Получено АПЗ на систему орошения, ведется работа по оформлению лицензии на недропользование. По проекту МТФ разработана ПСД, получено положительное заключение государственной экспертизы. Приобретены четыре трактора с навесным оборудованием и прицепами, выполнены агротехнические работы, создано 9 рабочих мест. В текущем году планируется перевод 250 га земель на орошаемое земледелие с применением влагосберегающих технологий. Финансирование проекта планируется через АО «АКК». В связи с отсутствием финансирования строительство МТФ перенесено на 2027 год. Проект реализуется поэтапно: создание кормовой базы, строительство МТФ с приобретением маточного поголовья КРС, а также строительство перерабатывающих цехов и расширение поголовья. Объем инвестиций в проект в 2025 году составил 1,2 млрд тенге. Дополнительно в текущем году инвестировано 200 млн тенге. Реализация проекта осуществляется в соответствии с бизнес-планом. | R12: 8 775 224 7474 ЫСҚАҚ ТАЛҒАТ БАТЫРҰЛЫ | S12: ЗУ на 5 лет. ЦН ЗУ - Пастбища.
A13: 5 | C13: Енбекшиказахский район | D13: ТОО «QazEcoDan», Масакский с/о | E13: Строительство Элеватора -комплекса по приемке, очистке, сушке и хранению зерновых и масленичных культур, производству комбинированных кормов | F13: Реализуемые проекты, прошедшие РКС | G13: 51 | I13: 7975.333 | K13: 7975.333 | M13: 1 этап - 2026 г. 2 этап - 2027 г. | N13: 1 этап - 2026 г. 2 этап - 2027 г. | O13: 9.6 | P13: Очистка, сушка: 40-60 тонн/час Хранение в силосах: 30 тыс. тонн Мощностью производства кормов 120 тонн/сутки | Q13: Строительство I очереди проекта завершено на 98%, акт ввода объекта в эксплуатацию находится на согласовании. Объем инвестиций составил 5,8 млрд тенге. Завершено строительство основных производственных объектов, включая сушильную печь, силосы, ЛЭП-35, газгольдер, железнодорожный тупик и монтаж технологического оборудования. На завершающей стадии находятся работы по объектам вспомогательной инфраструктуры. Для повышения эффективности проекта требуется подключение к природному газу, что позволит снизить себестоимость сушки зерновых культур. Также рассматривается расширение железнодорожного тупика путем строительства трех дополнительных веток. Вопрос строительства газопровода от п. Казтай Ултараков прорабатывается с местными исполнительными органами. | R13: 87716111117 Ерлан руководитель проекта, Руководитель Кайралапин Казбек +7 701 227 0091 | S13: ЗУ на 10 лет. ЦН ЗУ - Пастбища.
A14: 6 | C14: Енбекшиказахский район | D14: ТОО «Мың жылқы шаруа қожалығы», Масакский с/о Саймасай, Каратурык. | E14: Строительство и организация деятельности конефермы | F14: Реализуемые проекты, прошедшие РКС | G14: 20 | I14: 1576.6 | K14: 1576.6 | M14: 2027 г. | O14: 4457.7 | P14: 1 000 лошадей | Q14: Введутся работы по подготовке к СМР, произведен закуп лошадей в кол-ве 360 голов на 432 млн тенге. На 5 га планируется строительство кошары, навесов, загонов, остальную землю использовать под пастбище. | R14: Руководитель - Оразалин Галымжан Серикович 87011116911 | S14: ЗУ на 5 лет. ЦН ЗУ - Пастбища.
A15: 7 | C15: Енбекшиказахский район | D15: ТОО «K&J AGRO» | E15: Строительство теплицы по выращиванию шампиньонов | F15: Реализуемые проекты, прошедшие РКС в 2026 | G15: 100 | I15: 1500 | K15: 1500 | M15: 2029 | O15: 4 | P15: 2 тыс. тонн в год | Q15: Планируется заказ проектно-сметной документации. Ожидает подведения инфраструктуры на ИЗ «Шелек» | R15: Ракыш Темирлан | S15: нет
A16: 8 | C16: Жамбылский район | D16: ТОО «Кок Тениз К», Темиржолский с/о | E16: Расширение мощностей по переработке кукурузы с 10 000 до 50 000 тонн в год | F16: Реализуемые проекты, прошедшие РКС | G16: 20 | H16: СКО | I16: 750 | K16: 1500 | M16: 2029 г. | O16: 3080 | P16: 50 тыс тонн в год | Q16: 15.06.2026 г. планируется доставка трех дождевальных установок для орошения земельных участков общей площадью 200 га. Проводится работа по выбору поставщика дождевальных установок для организации орошения 1 000 га земель, предназначенных под многолетние культуры. Объем инвестиций в проект в текущем году составляет 750 млн тенге. Реализация проекта осуществляется в соответствии с утвержденным бизнес-планом. | R16: Кошкинов Ержан Абдулинович +77015396668, 8 706 407 9137 Ерасыл - сын | S16: ЗУ на 10 лет. ЦН ЗУ - пашня богарная
A17: 9 | C17: Жамбылский район | D17: ТОО «НПЦ Генофонд» | E17: Строительство МТФ на 600 голов КРС | F17: Реализуемые проекты, по линии кредитования АПК по опыту СКО | G17: 18 | H17: СКО | K17: 2400 | L17: 1400 | P17: 600 голов, 5000 тон в год | Q17: Завршение строительствв МТФ планируется в до конца июля месяца текущего года, для приобретения оборудования МТФ, доильного зала, КРС, Конкурсной комиссией утверждено финансирование на 1,4 млрд тенге. Финансирование планируется в текущем месяце. | R17: 8-701 303 5050 Толемисов Махан Кенжегазинович, бухгалтер - 8-701 303 22 88 Кумис Мурзалинова | S17: ПСД на стадии разработки, представлен государственный акт на земельный участок
A18: 10 | C18: Жамбылский район | D18: ТОО «Алматы құс фабрикасы Жетісу» | E18: Разведение птицы на мясо, племенной птицы и молодняка | G18: 6000 | H18: БРК и собственные средства | K18: 146300 | M18: 2028 г. | P18: 100 тыс тонн | Q18: ТОО «Алматы құс фабрикасы Жетісу», стс-сть 146,3 млрд тенге. Площадь - 5838,4 га. Проблемные вопросы: подведение инфраструктуры. Текущее состояние: ГЭ имеется, ожидается ПСД по инфраструктуре. ПСД по автодорогам и мостам подготовлена. Получено АПЗ и согласован эскизный проект.
A19: 11 | C19: Илийский район | D19: ТОО «Компания «Сары Булак», Аксайский с/о, село Аксай уч.1531 | E19: По переработке куриного помёта в органические удобрения | F19: Реализуемые проекты, прошедшие РКС | G19: 60 | I19: 550 | K19: 550 | M19: 2026 г. | N19: 2027 г. | O19: 6 | P19: Переработка куриного помёта – 200 тонн в сутки | Q19: Лагуны для хранения и переработки птичьего помета выполнены и забетонированы. Вопрос получения технических условий от АЖК остается нерешенным. Проведена повторная встреча с руководством АЖК, достигнута договоренность о повторной подаче документов на получение ТУ. Оборудование закуплено и находится на складах без монтажа и ввода в эксплуатацию. Получение акта ввода объекта в эксплуатацию планируется в 2027 году. | R19: 87012281400 Берик Меирханович | S19: ЦН ЗУ - пастбище
A20: 12 | C20: Илийский район | D20: ТОО «Alfalfa», Аксайский с/о | E20: Выращивание люцерны | F20: Реализуемые проекты, прошедшие РКС | G20: 30 | H20: СКО | I20: 5000 | K20: 5000 | L20: 1500 | M20: 2026 г. | O20: 1700 | P20: Тюкованная люцерна 12 000 тонн/год, гранулированная люцерна 8 000 тонн в год | Q20: Получено финансирование от АО «СПК Конаев» в размере 1,5 млрд тенге. На стадии завершения строительно-монтажные работы по внутренним сетям водоснабжения. Поставлены 8 дождевальных установок, не введены в эксплуатацию, 3 установки находятся в пути. В текущем году будут установленны 11 дождевальных машин покрывающих 700 га земли, в 2027 году планируется приобретение и установка дождевальных машин покрывающих оставшиеся 1000 га. Осуществляется поиск инвестора/инвестиций для строительства наружных сетей водоснабжения, проводится расчет окупаемости проекта. | R20: Руководитель - Яний Сергей Владимирович, Ауельбек 87017444703 | S20: Подведение недостающей ИКИ, ЦН ЗУ - пастбище
A21: 13 | C21: Илийский район | D21: ТОО «LUX Grand Park» | E21: Строительство молочно-товарной фермы в Илийском районе Алматинской области | F21: Реализуемые проекты, прошедшие РКС в 2026 | G21: 100 | I21: 650 | K21: 650 | M21: 2027 | O21: 282 | P21: 876 000 литров натурального молока в год | Q21: Получили выписку РКС | S21: нет
A22: 14 | C22: Илийский район | D22: ТОО «Агрофирма Dinara-Ranch» | E22: Растениеводство на орошаемых землях для создание кормовой базы КРС | F22: Реализуемые проекты, прошедшие РКС в 2026 | G22: 18 | I22: 700 | K22: 700 | M22: 2028 | O22: 390.2 | P22: 6 248 т. кормов в год | Q22: Начаты посевные работы
A23: 15 | C23: Илийский район | D23: АО «АЛЕЛЬ АГРО» | E23: Строительство завода по переработке отходов птицеводства (производство кормовых добавок из пера, кишок, крови, падежа) | F23: Реализуемые проекты, прошедшие РКС в 2026 | G23: 27 | I23: 670 | K23: 670 | M23: 2027 | O23: 3.2 | P23: 1.Линия переработки крови (4.5 т/день)2.Линия переработки кишок (9т/день)3. Линия переработки пера (9т/день) | Q23: Получили выписку от РКС | S23: нет
A24: 16 | C24: Карасайский район | D24: ТОО «Жигалма» (Caspian Beverage Holdings), Жамбылский с/о | E24: Производство безалкогольных напитков и минеральных вод | G24: 250 | I24: 15800 | K24: 15800 | L24: 5000 | M24: 2026 г. | N24: 2027 г. | O24: 10 | P24: 500 млн. литров продукции в год, 120 млн. единиц упаковки в год | Q24: Заявление на получение архитектурно-планировочного задания (АПЗ) направлено. Подана заявка в АЖК на ТУ -2 МВ (врменная). 24.04.2026 года получено официальное письмо от АЖК, согласно которому запланированы работы по увеличению мощности на подстанции «Чемолган», к которой будет осуществлено подключение объекта компании. Осуществляется поиск инвестора/инвестиций. | R24: Руководитель - Ахметов Алмат Сагындык улы, 87777799078, Рустам Давлетов +7 (777) 779 90 78 | S24: ЗУ на 3 года. ЦН ЗУ - пашня орошаемая
A25: 17 | C25: Талгарский район | D25: ТОО "ALATAU GREEN PRODUCTION" | E25: Строительство мультикультурного тепличного комплекса на 8 гектар | G25: 400 | H25: БРК | J25: 17300 | L25: 13408.8 | M25: 2025-2028 г. | O25: 8 | P25: 4 тыс тонн | Q25: Общая стоимость проекта составляет 17,3 млрд тенге. Финансирование осуществляется за счет собственных средств компании и кредита АО «Банк Развития Казахстана». Получены АПЗ и технические условия на подключение к инженерным сетям. Разрешение на строительство мостового перехода через Большой Алматинский канал получено. Проектно-сметная документация находится на завершающей стадии. Проект предусматривает создание 400 постоянных рабочих мест. Ввод объекта в эксплуатацию планируется до конца III квартала 2026 года, выход на полную проектную мощность — в 2027 году.
A26: 18 | C26: Уйгурский район | D26: ТОО «Rancho Hampshire», Малодиханский с/о | E26: Организация производственной базы сельхозназначения (Разведение английской породы овец Гемпшир и выращивание кукурузы, люцерны и разнотравья) | F26: Реализуемые проекты, прошедшие РКС | G26: 50 | I26: 1000 | K26: 1000 | M26: 1 этап 2026 г. 2 этап 2028 г. | N26: 1 этап 2026 г. 2 этап 2028 г. | O26: 1500 | P26: Проектная мощность на 2000 голов, факт более 400 голов | Q26: Текущее сосотояние: Проект находится на стадии реализации. Степень готовности – 50 %. Проблемные вопросы: ТОО зарегистрировано в Илийском районе. | R26: Директор - Чепис Сергей +7 701 555 22 28 | S26: ЗУ на 10 лет. ЦН ЗУ - пастбище.
A27: 19 | C27: Уйгурский район | D27: ТОО «Харвест Агро Холдинг» | E27: Создание агро-индустриального кластера «Harvest» в Уйгурском районе | F27: Реализуемые проекты, прошедшие РКС | G27: 60 | I27: 18200 | K27: 18200 | M27: 2029 г. | O27: 100 | P27: до 50 тыс. тонн кукурузы и 15 тыс. тонн сои в год | Q27: 30.01.2026 года состоялось заседание земельной комиссии, по итогам которого одобрено предоставление ЗУ площадью 3 000 га сроком на 10 лет из запрошенных 10 000 га на 49 лет. 27.03.2026 года проведены общественные слушания, где было одобрено выдача еще 2 000 га.
A28: 20 | C28: Уйгурский район | D28: ТОО «Harvesto Logistics» | E28: Строительство завода по производству семян гибридов кукурузы и подработке, хранению товарного зерна | F28: Реализуемые проекты, прошедшие РКС в 2026 | G28: 70 | I28: 3600 | K28: 3600 | M28: 2028 г. | O28: 100 | P28: до 108 тыс. тонн хранения с суточной переработкой до 1 200 тонн в сезон. | Q28: На стадии прохождения земельной комиссии | R28: Мурат Амангельдиевич | S28: нет
A29: 21 | C29: Уйгурский район | D29: ТОО «Kaz Corn» | E29: Освоение залежных земель для возделывания гибридов кукурузы и родительских форм путем внедрения водосберегающих технологий | F29: Реализуемые проекты, прошедшие РКС в 2026 | G29: 35 | I29: 8500 | K29: 8500 | M29: 2027 г | O29: 5000 | P29: 4 000 га товарной кукурузы, 1 000 га семеноводство | Q29: На стадии прохождения земельной комиссии | R29: Мурат Амангельдиевич | S29: нет
A30: 22 | C30: Уйгурский район | D30: Прима-Кус | E30: Строительство птицеводческого комплекса замкнутого цикла по производству и переработке мяса бройлера | G30: 140 | I30: 24477 | K30: 24477 | M30: 2028 г. | O30: 542 | Q30: ТОО «Прима Құс» — птицефабрика,строительство 3-й этап. Общая потребность в инвестициях составляет 13 500,0 млн тенге, финансирование проекта обеспечено в полном объеме. На текущий момент строительно-монтажные работы выполнены на 97,1%. Ввод объекта в эксплуатацию запланирован на декабрь 2026 года. После выхода на проектную мощность объем производства будет увеличен до 36 000 тонн мяса птицы в живом весе в год.
A31: 23 | C31: г.Конаев | D31: ТОО «Asian International Trading Company», Шенгельдинский с/о, участок Кербулак | E31: Строительство завода по производству комбикорма из плющенной кукурузы | F31: Реализуемые проекты, прошедшие РКС | G31: 158 | I31: 2110 | K31: 2110 | M31: 2029 г. | O31: 20 | P31: 150,0 тыс тонн в год | Q31: Работы по проекту в настоящее время не ведутся. Проект реализуется на территории, прилегающей к СЭЗ «Конаев». Руководитель компании находится в КНР и планирует прибыть в конце июня – начале июля текущего года. В связи с неактивностью инвестора предлагается вынести на заседание РКС по отзыву ЗУ. | R31: Лань Сяо Янь, 87055302473, Кристина 8 (706) 410 10 98 | S31: ЗУ на 1 год. ЦН ЗУ - прочие земли
A32: 24 | C32: г.Конаев | D32: ТОО «Smart Adam Agro» | E32: Выращивание прочих многолетних культур | G32: 19 | I32: 1200 | K32: 1200 | O32: 900 | P32: Выращивание и производство кормов 5 тыс. тонн / год | R32: Ибекеев Ержан Сембекулы
A33: 25 | C33: г.Конаев | D33: TOO «Arbo Volt» | E33: Строительство питомника с производственной базы | F33: Реализуемые проекты, прошедшие РКС | G33: 100 | I33: 2400 | K33: 2400 | M33: 2028 | O33: 109 | P33: 16 000 саженцев Paulownia Tomentosa | Q33: Получен гос акт. Начали разработку плана детальной планировки. Разработку ПДП планируется завершить в августе 2026 года. . | S33: нет
A34: 26 | C34: г.Алатау | D34: ТОО «Молочная Долина», | E34: Строительство МТФ на 1200 голов | F34: Реализуемые проекты, прошедшие РКС | G34: 100 | I34: 18700 | K34: 18700 | L34: 15000 | M34: 2028 г. | O34: 1300 | P34: 13,5 тыс. тонн в год | Q34: Проект готовится к направлению на ГЭ. На поливных ЗУ посеяно 250 га люцерны, кукурузы на корма. Вопрос частичного финансирования рассматривается АО "СПК Конаев". 03.06.2026г. при рассмотрении проект на Комиссии проект был направлен на доработку, так как отсутствовало ПСД и другие документы, разрезающие строительство МТФ на территории города Алатау. | R34: Разумовский Дмитрий Михайлович +7 705 677 9447 dmitriy.r.kz@icloud.com | S34: ЗУ на 49 лет. ЦН ЗУ - пастбище.
A35: 27 | C35: г.Алатау | D35: ТОО «ПепсиКо ЦА» | E35: Завод по производству соленых закусок | F35: Реализуемые проекты, прошедшие РКС | G35: 300 | I35: 81000 | K35: 81000 | L35: 71000 | M35: 2026 г. | N35: 2026 г. | O35: 26.47 | P35: 21 тыс. тонн продукта (чипсы Lay's) | Q35: Ведутся СМР | R35: Маргулан +7 701 722 2727 | S35: ЗУ на 4 года 11 мес. ЦН ЗУ - 15,0га- пашня орошаемая, 11,5 га - пастбища
A36: 28 | C36: Райымбекский район | D36: ТОО «QARASAZ MILK» | E36: Производственное предприятие по переработке шкур | F36: Реализуемые проекты, прошедшие РКС в 2026 | G36: 30 | I36: 700 | K36: 700 | M36: 2027 г. | O36: 13 | P36: Переработка шкур КРС и МРС – порядка 10 000 штук в год. | Q36: На стадии оформления земельного участка | R36: Алиева Дамира Нурболовна +7 777 777 1788 | S36: З/У

Sheet Расширение
D2: кол | E2: сумма | F2: Раб. места
C3: Расширение | D3: 2 | E3: 3972.2 | F3: 60
A6: № | B6: № | C6: Район | D6: Наименование компании | E6: Наименование проекта | F6: Стадия проекта | G6: Раб. Места | H6: Финансирование | I6: Стоимость, млн. тенге | M6: Ввод объекта по РКС | N6: Ввод объекта по факту | O6: Площадь земельного участка, га | P6: Мощность проекта и производительность | Q6: Текущий статус | R6: ФИО руководителя, контакты | S6: Меры господдержки
H7: Собственные, АКК/БРК, Растениевод, СКО | I7: Всего по РКС | J7: Вне РКС | K7: Актуализир. сумма | L7: в т.ч. заемные
A8: 1 | C8: Жамбылский район | D8: ТОО «Happy Farm» | E8: Строительство молочно товарной фермы | F8: Реализуемые проекты, по линии кредитования АПК по опыту СКО | H8: СКО | K8: 1472.2 | L8: 1472.2 | P8: 408 голов, 2000 тонн в год | Q8: СМР не завершен, срок завершения строительства планируется на 10.2026 года, скот и оборудование завезено в полном объеме, монтаж доильного зала завершен, начаты пусконаладачные работы. | R8: Маметов Марат
A9: 2 | C9: Карасайский район | D9: АО "АзияАгроФуд" | E9: Глубокая переработка по переработке сельскохозяйственной продукции. Приобретение оборудования. | G9: 60 | H9: СКО | K9: 2500 | L9: 2500 | P9: 110 тыс тонн в год | Q9: Произведена предоплата за изготовление оборудования в размере 60% от суммы контрактов. Срок поставки оборудования по контракту август 2026 года. Начало монтажа приобретенного оборудования запланирована на сентябрь 2026 года. | R9: Ашенов Саян | S9: Кредитов АПК (СКО)

Sheet Проблемные
D2: кол | E2: сумма | F2: Раб. места
C3: Проблемные | D3: 14 | E3: 190415 | F3: 1079
A6: № | B6: № | C6: Район | D6: Наименование компании | E6: Наименование проекта | F6: Стадия проекта | G6: Раб. Места | H6: Финансирование | I6: Стоимость, млн. тенге | M6: Ввод объекта по РКС | N6: Ввод объекта по факту | O6: Площадь земельного участка, га | P6: Мощность проекта и производительность | Q6: Текущий статус | R6: ФИО руководителя, контакты | S6: Меры господдержки
H7: Собственные, АКК/БРК, Растениевод, СКО | I7: Всего по РКС | J7: Вне РКС | K7: Актуализир. сумма | L7: в т.ч. заемные
A8: 1 | C8: Балхашский район | D8: ТОО «Тайда животноводство», Бакбактинский с/о | E8: Строительство агропромышленного комплекса по производству яиц | F8: Проблемный | G8: 68 | I8: 3120 | K8: 3120 | M8: 2027 г. | N8: 2027 г. | O8: 50 | P8: 100 млн. яиц в год | Q8: ПСД на государственной экспертизе с 28.04,2026 года, еще не получено, так как срок рассмотрения 1,5 месяца. Ориентировочный выход с ГЭ 20.06.2026г. В связи с неактивностью инвестора предлагается вынести на заседание РКС по отзыву ЗУ. | R8: Руководитель - Ян Цинхай, Уаджитова Амина Абдримовна, 87076408018 | S8: ЗУ на 5 лет. ЦН ЗУ - Прочие земли.
A9: 2 | C9: Енбекшиказахский район | D9: ТОО «AGROFINANCE», ИЗ «Шелек» | E9: Строительство ультрасовременного фруктохранилища в Алматинской области | F9: Проблемный | G9: 40 | I9: 10500 | K9: 10500 | M9: 2028 г. | O9: 5 | P9: 10 000 тонн | Q9: Проект планируется к реализации на территории ИЗ «Шелек». Начало работ по подведению ИКИ ожидается через 2 месяца, завершение — в 2027 году. Проведены переговоры с инвестором. В настоящее время инвестор находится за границей. Представитель инвестора 30.06.2026 г. связался с работниками УКИЗ договорились о выезде 07.07.2026 г. чтоб рассмотреть предложения по новым ЗУ. Но сегодня так и не приехал, сославшись что выехал за границу, как будет в Алматы выйдет на связь. В связи с неактивностью инвестора предлагается вынести на заседание РКС по отзыву ЗУ. . | R9: 87781075132 Пасков Иван Степанович | S9: Размещение ИЗ «Шелек». ЦН ЗУ - Пастбища.
